Workbook

Sheet Hints 

Sheet Ch 10 Ans.
A1: ='10.1'!A1 -> 10.1 | C1: Pt Value
A2: ='10.1'!A2 -> Part A.
A3: ='10.1'!A3 -> Null Hypothesis | B3: ='10.1'!$B3 -> u new battery <= u old battery | C3: 2
A4: ='10.1'!A4 -> Alternative Hypothesis | B4: ='10.1'!$B4 -> u new battery >= u old battery
A5: ='10.1'!A5 -> Part B.
A6: ='10.1'!A6 -> Type I Error | B6: ='10.1'!$B6 -> Type I error would occur if we reject the null hypothesis when it is actually true. This means concluding that the new battery operates longer than the old battery when it does not. | C6: 2
A7: ='10.1'!A7 -> Part C.
A8: ='10.1'!A8 -> Type II Error | B8: ='10.1'!$B8 -> Type II error would occur if we fail to reject the null hypothesis when it is actually false. This means concluding that the new battery does not operate longer than the old battery when it does. | C8: 2
A9: ='10.1'!A9 -> Parts D & E
A10: ='10.1'!A10 -> type of test | B10: ='10.1'!$B10 -> Pooled-Variance t test | C10: 2
A11: ='10.1'!A11 -> Upper or Lower Tailed Test | B11: ='10.1'!$B11 -> Upper Tailed | C11: 2
A12: ='10.1'!A12 -> test Statistic Value | B12: ='10.1'!$B12 -> -3.0104781 | C12: 1
A13: ='10.1'!A13 -> p-Value | B13: ='10.1'!$B13 -> 0.9985 | C13: 2
A14: ='10.1'!A14 -> Decision | B14: ='10.1'!$B14 -> Do Not Reject the Null Hypothesis | C14: 1
A15: ='10.1'!A15 -> State your decision Relative to the Problem | B15: ='10.1'!$B15 -> There is not enough evidence to conclude that the new battery operates longer than the old battery. | C15: 2
A17: ='10.2'!A1 -> 10.2 Part A F Test
A18: ='10.2'!A2 -> p-value | B18: ='10.2'!B2 -> 0.020617462 | C18: 2
A19: ='10.2'!A3 -> Are the variances equal? | B19: ='10.2'!B3 -> No | C19: 2
A20: ='10.2'!A4 -> Part B
A21: ='10.2'!A5 -> type of test | B21: ='10.2'!B5 -> Pooled-Variance t test | C21: 2
A22: ='10.2'!A6 -> Part C | B22: ='10.2'!B6 -> 0
A23: ='10.2'!A7 -> Ho | B23: ='10.2'!B7 -> U = U | C23: 2
A24: ='10.2'!A8 -> Ha | C24: 1
A25: ='10.2'!A9 -> test Statistic Value | B25: ='10.2'!B9 -> 2.251 | C25: 1
A26: ='10.2'!A10 -> p -value | B26: ='10.2'!B10 -> 0.0371 | C26: 1
A27: ='10.2'!A11 -> Decision | B27: ='10.2'!B11 -> Reject The Null Hypothesis | C27: 1
A28: ='10.2'!A12 -> State your decision Relative to the Problem | B28: ='10.2'!B12 -> There is a significant difference between the variances of the two rivers. We can conclude that the variability in measurements between River A and River B is are not the same. | C28: 2
A30: 10.3
A31: ='10.3'!A1 -> Null Hypothesis | B31: ='10.3'!B1 -> U1 - U2 = 0 | C31: 2
A32: ='10.3'!A2 -> Alternative Hypothesis | B32: ='10.3'!B2 -> U 1- U2 <> 0
A34: ='10.3'!A4 -> type of test | B34: ='10.3'!B4 -> Paired Difference Test | C34: 2
A35: ='10.3'!A5 -> Tail? | B35: ='10.3'!B5 -> Two Tailed | C35: 2
A36: ='10.3'!A6 -> test Statistic Value | B36: ='10.3'!B6 -> 0.8622955 | C36: 2
A37: ='10.3'!A7 -> p -value | B37: ='10.3'!B7 -> 0.39927811 | C37: 1
A38: ='10.3'!A8 -> Decision | B38: ='10.3'!B8 -> Do Not Reject the Null Hypothesis | C38: 1
A39: ='10.3'!A9 -> State your decision Relative to the Problem | B39: ='10.3'!B9 -> The mean run times for the two sets of runners are not significantly different. We do not have sufficient evidence to conclude that the new carbohydrate-protein formula leads to a different mean run time compared to the carbohydrate-only formula. | C39: 2
A40: ='10.3'!A10 -> Part B. | B40: ='10.3'!B10 -> 0
A41: ='10.3'!A11 -> Assumption: | B41: ='10.3'!B11 -> The differences in the distances run are normally distributed. | C41: 2
A42: ='10.3'!A12 -> Part C. | B42: ='10.3'!B12 -> 0
B43: ='10.3'!B13 -> Show graph on right | C43: 2
...

Sheet Ch11 Ans.
A1: Week 5 Homework - Chapter 11 | C1: Pts
A2: ='11.1'!A1 -> 11.1A
A3: ='11.1'!A2 -> Null Hypothesis | B3: ='11.1'!B2 -> U1=U2=U3=U4 | C3: 2
A4: ='11.1'!A3 -> Alternative Hypothesis | B4: ='11.1'!B3 -> Not all means are equal
A6: ='11.1'!A5 -> F Statistic Value | B6: ='11.1'!B5 -> 5.1 | C6: 2
A7: ='11.1'!A6 -> pvalue | B7: ='11.1'!B6 -> 0.00283 | C7: 2
A8: ='11.1'!A7 -> Decision | B8: ='11.1'!B7 -> Reject The Null Hypothesis | C8: 2
A9: ='11.1'!A8 -> State your decision Relative to the Problem | B9: ='11.1'!B8 -> Not all the means are equal | C9: 2
A10: ='11.1'!A9 -> Part B.
A11: ='11.1'!A11 -> Capital Area and Great Lakes | B11: ='11.1'!B11 -> 0
A12: ='11.1'!A12 -> Capital Area and Mid-Atlantic | B12: ='11.1'!B12 -> x | C12: 4
A13: ='11.1'!A13 -> Capital Area and New England | B13: ='11.1'!B13 -> 0
A14: ='11.1'!A14 -> Great Lakes and Mid-Atlantic | B14: ='11.1'!B14 -> 0
A15: ='11.1'!A15 -> Great Lakes and New England | B15: ='11.1'!B15 -> x
A16: ='11.1'!A16 -> Mid-Atlantic and New England | B16: ='11.1'!B16 -> x
A18: ='11.2'!A1 -> 11.2A
A19: ='11.2'!A2 -> Null Hypothesis | B19: ='11.2'!B2 -> U1=U2=U3=U4 | C19: 2
A20: ='11.2'!A3 -> Decision | B20: ='11.2'!B3 -> Reject the Null
A22: ='11.2'!A5 -> Part B. | B22: ='11.2'!B5 -> 0 | C22: 2
A23: ='11.2'!A6 -> 0 | B23: ='11.2'!B6 -> 0 | C23: 2
A24: ='11.2'!A7 -> Conclusion relative to the problem | B24: ='11.2'!B7 -> There is no significant evidence to suggest a difference in the mean sales among the food product types. | C24: 2
A25: ='11.2'!A8 -> Alternative Hypothesis
A26: ='11.2'!A9 -> Null Hypothesis | B26: ='11.2'!B9 -> Var1=Var2=Var3=Var4 | C26: 2
A27: ='11.2'!A10 -> Alternative Hypothesis | B27: ='11.2'!B10 -> All the var are not equal
A29: ='11.2'!A12 -> F Statistic value | B29: ='11.2'!B12 -> 0.23155297 | C29: 2
A30: ='11.2'!A13 -> Decision | B30: ='11.2'!B13 -> Fail to reject the null | C30: 2
A31: ='11.2'!A14 -> Conclusion relative to the problem | B31: ='11.2'!B14 -> Ther is no significant evidence to suggest a difference in the variation of sales among the food product types. | C31: 2
A32: ='11.2'!A15 -> Part C.
A33: ='11.2'!A16 -> Select the most appropriate answers: | B33: ='11.2'!B16 -> No violation | C33: 2
B34: ='11.2'!B17 -> valid | C34: 2
A35: ='11.2'!A18 -> Part D
A36: ='11.2'!A19 -> If Appropriate, Highlight the food type that differ in mean sales | B36: ='11.2'!B19 -> Burger | C36: 2
B37: ='11.2'!B20 -> Chicken
B38: ='11.2'!B21 -> Sandwich
B39: ='11.2'!B22 -> Snack
A41: ='11.3'!A1 -> 11.3
A42: ='11.3'!A2 -> Parts A, B, & C
A43: ='11.3'!A3 -> Sunlight & Water Interaction? | B43: ='11.3'!B3 -> No | C43: 2
A44: ='11.3'!A4 -> P-value? | B44: ='11.3'!B4 -> 0.23394201 | C44: 2
A45: ='11.3'!A5 -> Sunlight? | B45: ='11.3'!B5 -> Yes | C45: 2
...

Sheet 10.1
A1: 10.1
A2: Part A.
A3: Null Hypothesis | B3: u new battery <= u old battery
A4: Alternative Hypothesis | B4: u new battery >= u old battery
A5: Part B.
A6: Type I Error | B6: Type I error would occur if we reject the null hypothesis when it is actually true. This means concluding that the new battery operates longer than the old battery when it does not.
A7: Part C.
A8: Type II Error | B8: Type II error would occur if we fail to reject the null hypothesis when it is actually false. This means concluding that the new battery does not operate longer than the old battery when it does.
A9: Parts D & E
A10: type of test | B10: Pooled-Variance t test | D10: Pooled-Variance t Test for Differences in Two Means
A11: Upper or Lower Tailed Test | B11: Upper Tailed | D11: (assumes equal population variances)
A12: test Statistic Value | B12: =E31 -> -3.0104781 | D12: Data | G12: Confidence Interval Estimate
A13: p-Value | B13: 0.9985 | D13: Hypothesized Difference | E13: 0 | G13: for the Difference Between Two Means
A14: Decision | B14: Do Not Reject the Null Hypothesis | D14: Level of Significance | E14: 0.05
A15: State your decision Relative to the Problem | B15: There is not enough evidence to conclude that the new battery operates longer than the old battery. | D15: Population 1 Sample | G15: Data
D16: Sample Size | E16: 95 | G16: Confidence Level | H16: 0.95
D17: Sample Mean | E17: 12
D18: Sample Standard Deviation | E18: =8.4 -> 8.4 | G18: Intermediate Calculations
D19: Population 2 Sample | G19: Degrees of Freedom | H19: =E25 + E26 -> 192
D20: Sample Size | E20: 99 | G20: t Value | H20: =_xlfn.T.INV.2T(1 - H16, H19) -> 1.9723965
D21: Sample Mean | E21: 16 | G21: Interval Half Width | H21: =(H20 * SQRT(E28 * (1/E16 + 1/E20))) -> 2.6207087
D22: Sample Standard Deviation | E22: 10
G23: Confidence Interval
D24: Intermediate Calculations | G24: Interval Lower Limit | H24: =E30 - H21 -> -6.6207087
D25: Population 1 Sample Degrees of Freedom | E25: =E16 - 1 -> 94 | G25: Interval Upper Limit | H25: =E30 + H21 -> -1.3792913
D26: Population 2 Sample Degrees of Freedom | E26: =E20 - 1 -> 98
D27: Total Degrees of Freedom | E27: =E25 + E26 -> 192
D28: Pooled Variance | E28: =((E25 * E18^2) + (E26 * E22^2))/E27 -> 85.586667
D29: Standard Error | E29: =SQRT(E28 * (1/E16 + 1/E20)) -> 1.3286926
D30: Difference in Sample Means | E30: =E17 - E21 -> -4
D31: t Test Statistic | E31: =(E30 - E13)/E29 -> -3.0104781
D33: Upper-Tail Test | G33: One-Tail Calculations
D34: Upper Critical Value | E34: =(_xlfn.T.INV.2T(2*E14,E27)) -> 1.6528286 | G34: T.DIST.RT value | H34: =_xlfn.T.DIST.RT(ABS(E31), E27) -> 0.0014794524
D35: p-Value | E35: =IF(E31 < 0, H35, H34) -> 0.99852055 | G35: 1 - T.DIST.RT value | H35: =1 - H34 -> 0.99852055
D36: =IF(E35 < E14,"Reject the null hypothesis","Do not reject the null hypothesis") -> Do not reject the null hypothesis

Sheet 10.2
A1: 10.2 Part A F Test | C1: River A | D1: River B
A2: p-value | B2: =E15 -> 0.020617462 | C2: 8.968143 | D2: 6.670441
A3: Are the variances equal? | B3: No | C3: 9.11974 | D3: 4
A4: Part B | C4: 9.413058 | D4: 10
A5: type of test | B5: Pooled-Variance t test | C5: 8.665746 | D5: 8
A6: Part C | C6: 9.937042 | D6: 7.5
A7: Ho | B7: U = U | C7: 8.280083 | D7: 7.422487
A8: Ha | B8: U not equal U | C8: 7.864158 | D8: 6.563322
A9: test Statistic Value | B9: 2.251 | C9: 7.509577 | D9: 8.5
A10: p -value | B10: 0.0371 | C10: 9.181173 | D10: 8
A11: Decision | B11: Reject The Null Hypothesis | C11: 7.676255 | D11: 9
A12: State your decision Relative to the Problem | B12: There is a significant difference between the variances of the two rivers. We can conclude that the variability in measurements between River A and River B is are not the same. | C12: 8
C13: 8.3
C15: =_xlfn.VAR.S(C2:C13) -> 0.57507779 | D15: =_xlfn.VAR.S(D2:D11) -> 2.6420529 | E15: =_xlfn.F.TEST(C2:C13,D2:D11) -> 0.020617462
E16: 0.05
B18: Pooled-Variance t Test for Differences in Two Means
B19: (assumes equal population variances)
B20: Data | E20: Confidence Interval Estimate
B21: Hypothesized Difference | C21: 0 | E21: for the Difference Between Two Means
B22: Level of Significance | C22: 0.05
B23: Population 1 Sample | E23: Data
B24: Sample Size | C24: 12 | E24: Confidence Level | F24: 0.95
B25: Sample Mean | C25: =AVERAGE(C2:C13) -> 8.5762479
B26: Sample Standard Deviation | C26: =_xlfn.STDEV.S(C2:C13) -> 0.75833884 | E26: Intermediate Calculations
B27: Population 2 Sample | E27: Degrees of Freedom | F27: =C33 + C34 -> 18
B28: Sample Size | C28: =COUNT($B:$B) -> 10 | E28: t Value | F28: =_xlfn.T.INV.2T(1 - F24, F27) -> 2.100922
B29: Sample Mean | C29: =AVERAGE(D2:D11) -> 7.565625 | E29: Interval Half Width | F29: =(F28 * SQRT(C36 * (1/C24 + 1/C28))) -> 38.36029
B30: Sample Standard Deviation | C30: =_xlfn.STDEV.S(D2:D11) -> 1.6254393
E31: Confidence Interval
B32: Intermediate Calculations | E32: Interval Lower Limit | F32: =C38 - F29 -> 2.7397102
B33: Population 1 Sample Degrees of Freedom | C33: =C24 - 1 -> 11 | E33: Interval Upper Limit | F33: =C38 + F29 -> 79.46029
B34: Population 2 Sample Degrees of Freedom | C34: =C28 - 1 -> 9
B35: Total Degrees of Freedom | C35: =C33 + C34 -> 18
B36: Pooled Variance | C36: =((C33 * C26^2) + (C34 * C30^2))/C35 -> 1666.9167
B37: Standard Error | C37: =SQRT(C36 * (1/C24 + 1/C28)) -> 18.258788
B38: Difference in Sample Means | C38: =C25 - C29 -> 1.0106229
B39: t Test Statistic | C39: =(C38 - C21)/C37 -> 2.2509709
B41: Two-Tail Test
B42: Lower Critical Value | C42: =-(_xlfn.T.INV.2T(C22, C35)) -> -2.100922
B43: Upper Critical Value | C43: =_xlfn.T.INV.2T(C22, C35) -> 2.100922
...

Sheet 10.3
A1: Null Hypothesis | B1: U1 - U2 = 0
A2: Alternative Hypothesis | B2: U 1- U2 <> 0
A4: type of test | B4: Paired Difference Test
A5: Tail? | B5: Two Tailed
A6: test Statistic Value | B6: =G33 -> 0.8622955
A7: p -value | B7: =G38 -> 0.39927811
A8: Decision | B8: Do Not Reject the Null Hypothesis
A9: State your decision Relative to the Problem | B9: The mean run times for the two sets of runners are not significantly different. We do not have sufficient evidence to conclude that the new carbohydrate-protein formula leads to a different mean run time compared to the carbohydrate-only formula.
A10: Part B.
A11: Assumption: | B11: The differences in the distances run are normally distributed.
A12: Part C.
B13: Show graph on right
A14: Part D.
A15: CI. Lower Bound | B15: =G36 -> -2.0930241
A16: CI Upper Bound | B16: =G37 -> 2.0930241
A17: Interpretation of CI
A19: Carb | B19: Carb_Protein | D19: Average | E19: STD Dev
A20: 9.72 | B20: 9.81 | C20: =ABS(A20-B20) -> 0.09 | D20: =AVERAGE(C20:C39) -> 0.14 | E20: =_xlfn.STDEV.S($D$20,C20:C39) -> 0.076059187 | F20: 20 | G20: =_xlfn.T.INV.2T(0.05,19) -> 2.0930241 | H20: =G20*(E20/SQRT(20)) -> 0.035596795
A21: 10.08 | B21: 10.215 | C21: =ABS(A21-B21) -> 0.135 | I21: Lower Bound | J21: =D20-H20 -> 0.1044032
A22: 10.17 | B22: 10.305 | C22: =ABS(A22-B22) -> 0.135 | F22: Paired t Test | I22: Upper Bound | J22: =D20+H20 -> 0.1755968
A23: 10.575 | B23: 10.53 | C23: =ABS(A23-B23) -> 0.045 | F23: Data
A24: 10.575 | B24: 10.755 | C24: =ABS(A24-B24) -> 0.18 | F24: Hypothesized Mean Diff. | G24: 0 | J24: 0.095, 0.176
A25: 10.755 | B25: 10.98 | C25: =ABS(A25-B25) -> 0.225 | F25: Level of Significance | G25: 0.05
A26: 10.8 | B26: 11.07 | C26: =ABS(A26-B26) -> 0.27
A27: 10.89 | B27: 11.115 | C27: =ABS(A27-B27) -> 0.225 | F27: Intermediate Calculations
A28: 10.98 | B28: 11.16 | C28: =ABS(A28-B28) -> 0.18 | F28: Sample Size | G28: 20
A29: 11.07 | B29: 11.35 | C29: =ABS(A29-B29) -> 0.28 | F29: DBar | G29: =AVERAGE(C20:C39) -> 0.14
A30: 11.25 | B30: 11.385 | C30: =ABS(A30-B30) -> 0.135 | F30: degrees of freedom | G30: =G28 - 1 -> 19
A31: 11.43 | B31: 11.52 | C31: =ABS(A31-B31) -> 0.09 | F31: SD | G31: =SQRT(DEVSQ(A:A)/G30) -> 0.72608408
A32: 11.61 | B32: 11.7 | C32: =ABS(A32-B32) -> 0.09 | F32: Standard Error | G32: =G31/SQRT(G28) -> 0.16235734
A33: 11.655 | B33: 11.745 | C33: =ABS(A33-B33) -> 0.09 | F33: t Test Statistic | G33: =(G29 - G24)/G32 -> 0.8622955
A34: 11.745 | B34: 11.79 | C34: =ABS(A34-B34) -> 0.045
A35: 11.79 | B35: 11.88 | C35: =ABS(A35-B35) -> 0.09 | F35: Two-Tailed Test
A36: 11.79 | B36: 12.015 | C36: =ABS(A36-B36) -> 0.225 | F36: Lower Critical Value | G36: =-_xlfn.T.INV.2T(G25, G30) -> -2.0930241
A37: 11.925 | B37: 12.105 | C37: =ABS(A37-B37) -> 0.18 | F37: Upper Critical Value | G37: =_xlfn.T.INV.2T(G25, G30) -> 2.0930241
A38: 12.15 | B38: 12.24 | C38: =ABS(A38-B38) -> 0.09 | F38: p-Value | G38: =_xlfn.T.DIST.2T(ABS(G33), G30) -> 0.39927811
A39: 12.375 | B39: 12.375 | C39: =ABS(A39-B39) -> 0 | F39: =IF(G38 < G25, "Reject the null hypothesis", "Do not reject the null hypothesis") -> Do not reject the null hypothesis

Sheet 11.1
A1: 11.1A | P1: Tukey Kramer Multiple Comparisons
A2: Null Hypothesis | B2: U1=U2=U3=U4
A3: Alternative Hypothesis | B3: Not all means are equal | Q3: Sample | R3: Sample | U3: Absolute | V3: Std. Error | W3: Critical
P4: Group | Q4: Mean | R4: Size | T4: Comparison | U4: Difference | V4: of Difference | W4: Range | X4: =IF(Q15="","Results are NOT valid until Q Statistic is entered into B15","Results") -> Results
A5: F Statistic Value | B5: 5.1 | P5: ="1: " & 'One Way Anova'!P5 -> 1: | Q5: =K12 -> 17.857143 | R5: =I12 -> 14 | T5: Group 1 to Group 2 | U5: =ABS(Q5-Q6) -> 38.714286 | V5: =SQRT(($K$21/2)*((1/R5)+(1/R6))) -> 11.64433 | W5: =$Q$15*V5 -> 43.549794 | X5: =IF(U5>W5,"Means are different","Means are not different") -> Means are not different
A6: pvalue | B6: 0.00283 | P6: ="2: " & 'One Way Anova'!P6 -> 2: | Q6: =K13 -> 56.571429 | R6: =I13 -> 21 | T6: Group 1 to Group 3 | U6: =ABS(Q5-Q7) -> 41.487685 | V6: =SQRT((K21/2)*((1/R5)+(1/R7))) -> 10.983111 | W6: =$Q$15*V6 -> 41.076834 | X6: =IF(U6>W6,"Means are different","Means are not different") -> Means are different
A7: Decision | B7: Reject The Null Hypothesis | P7: ="3: " & 'One Way Anova'!P7 -> 3: | Q7: =K14 -> 59.344828 | R7: =I14 -> 29 | T7: Group 1 to Group 4 | U7: =ABS(Q5-Q8) -> 3.2460317 | V7: =SQRT((K21/2)*((1/R5)+(1/R8))) -> 12.026212 | W7: =$Q$15*V7 -> 44.978034 | X7: =IF(U7>W7,"Means are different","Means are not different") -> Means are not different
A8: State your decision Relative to the Problem | B8: Not all the means are equal | C8: Capital Region | D8: Great Lakes | E8: Mid-Atlantic | F8: New England | H8: Anova: Single Factor | P8: ="4: " & 'One Way Anova'!P8 -> 4: | Q8: =K15 -> 14.611111 | R8: =I15 -> 18 | T8: Group 2 to Group 3 | U8: =ABS(Q6-Q7) -> 2.773399 | V8: =SQRT((K21/2)*((1/R6)+(1/R7))) -> 9.6700897 | W8: =$Q$15*V8 -> 36.166135 | X8: =IF(U8>W8,"Means are different","Means are not different") -> Means are not different
A9: Part B. | C9: 13 | D9: 156 | E9: 274 | F9: 31 | T9: Group 2 to Group 4 | U9: =ABS(Q6-Q8) -> 41.960317 | V9: =SQRT((K21/2)*((1/R6)+(1/R8))) -> 10.840281 | W9: =$Q$15*V9 -> 40.542652 | X9: =IF(U9>W9,"Means are different","Means are not different") -> Means are different
A10: If you did find a difference in the means which ones were different? Place an X by the ones that were different | C10: 14 | D10: 262 | E10: 154 | F10: 16 | H10: SUMMARY | P10: Other Data | T10: Group 3 to Group 4 | U10: =ABS(Q7-Q8) -> 44.733716 | V10: =SQRT((K21/2)*((1/R7)+(1/R8))) -> 10.126697 | W10: =$Q$15*V10 -> 37.873847 | X10: =IF(U10>W10,"Means are different","Means are not different") -> Means are different
A11: Capital Area and Great Lakes | C11: 29 | D11: 148 | E11: 172 | F11: 10 | H11: Groups | I11: Count | J11: Sum | K11: Average | L11: Variance | P11: Level of significance | Q11: ='One Way Anova'!V17 -> 0
A12: Capital Area and Mid-Atlantic | B12: x | C12: 18 | D12: 61 | E12: 144 | F12: 18 | H12: Capital Region | I12: 14 | J12: 250 | K12: 17.857143 | L12: 44.747253 | P12: Numerator d.f. | Q12: ='One Way Anova'!Y2 -> 0
A13: Capital Area and New England | C13: 33 | D13: 54 | E13: 109 | F13: 30 | H13: Great Lakes | I13: 21 | J13: 1188 | K13: 56.571429 | L13: 3666.1571 | P13: Denominator d.f. | Q13: ='One Way Anova'!R14 -> 0
A14: Great Lakes and Mid-Atlantic | C14: 11 | D14: 58 | E14: 90 | F14: 12 | H14: Mid-Atlantic | I14: 29 | J14: 1721 | K14: 59.344828 | L14: 3676.8768 | P14: MSW | Q14: =K21 -> 2277.9191
A15: Great Lakes and New England | B15: x | C15: 19 | D15: 57 | E15: 78 | F15: 17 | H15: New England | I15: 18 | J15: 263 | K15: 14.611111 | L15: 48.251634 | P15: Q Statistic | Q15: 3.74
A16: Mid-Atlantic and New England | B16: x | C16: 10 | D16: 33 | E16: 37 | F16: 15
C17: 11 | D17: 27 | E17: 73 | F17: 17
C18: 16 | D18: 32 | E18: 54 | F18: 8 | H18: ANOVA
C19: 21 | D19: 44 | E19: 72 | F19: 20 | H19: Source of Variation | I19: SS | J19: df | K19: MS | L19: F | M19: P-value | N19: F crit
C20: 15 | D20: 27 | E20: 60 | F20: 14 | H20: Between Groups | I20: 34840.411 | J20: 3 | K20: 11613.47 | L20: 5.0982805 | M20: 0.0028324508 | N20: 2.7217834
C21: 19 | D21: 24 | E21: 36 | F21: 10 | H21: Within Groups | I21: 177677.69 | J21: 78 | K21: 2277.9191
C22: 21 | D22: 24 | E22: 41 | F22: 9
D23: 20 | E23: 29 | F23: 7 | H23: Total | I23: 212518.1 | J23: 81
D24: 55 | E24: 35 | F24: 8
D25: 17 | E25: 38 | F25: 11
D26: 23 | E26: 21 | F26: 10
D27: 26 | E27: 25
D28: 17 | E28: 37
D29: 23 | E29: 28
E30: 11
E31: 16
E32: 23
E33: 8
E34: 8
E35: 16
E36: 17
E37: 15

Sheet 11.2
A1: 11.2A | C1: Burger | D1: Chicken | E1: Sandwich | F1: Snack
A2: Null Hypothesis | B2: U1=U2=U3=U4 | C2: 1200 | D2: 713.7 | E2: 490 | F2: 207.9
A3: Decision | B3: Reject the Null | C3: 1510 | D3: 1298 | E3: 360 | F3: 659
A4: F Statistic value | B4: =L21 -> 0.75522391 | C4: 1380.9 | D4: 1298 | E4: 878.8 | F4: 737
A5: Part B. | C5: 2500 | D5: 2846.5 | E5: 895 | F5: 872.7
C6: 1310 | D6: 974 | E6: 921 | F6: 1125
A7: Conclusion relative to the problem | B7: There is no significant evidence to suggest a difference in the mean sales among the food product types. | C7: 2096 | D7: 1727.8 | E7: 2399.8 | F7: 1310
A8: Alternative Hypothesis | B8: Not all means are equal | C8: 1268.2 | D8: 942 | E8: 2465 | F8: 2565 | S8: *Differences from the Median by group
A9: Null Hypothesis | B9: Var1=Var2=Var3=Var4 | H9: Anova: Single Factor | N9: Burger | O9: Chicken | P9: Sandwich | Q9: Snack | S9: Burger | T9: Chicken | U9: Sandwich | V9: Snack
A10: Alternative Hypothesis | B10: All the var are not equal | N10: =MEDIAN(C2:C8) -> 1380.9 | O10: =MEDIAN(D2:D8) -> 1298 | P10: =MEDIAN(E2:E8) -> 895 | Q10: =MEDIAN(F2:F8) -> 872.7 | S10: =ABS($N$10-C2) -> 180.9 | T10: =ABS($O$10-D2) -> 584.3 | U10: =ABS($P$10-E2) -> 405 | V10: =ABS($Q$10-F2) -> 664.8
H11: SUMMARY | S11: =ABS($N$10-C3) -> 129.1 | T11: =ABS($O$10-D3) -> 0 | U11: =ABS($P$10-E3) -> 535 | V11: =ABS($Q$10-F3) -> 213.7
A12: F Statistic value | B12: =W31 -> 0.23155297 | H12: Groups | I12: Count | J12: Sum | K12: Average | L12: Variance | S12: =ABS($N$10-C4) -> 0 | T12: =ABS($O$10-D4) -> 0 | U12: =ABS($P$10-E4) -> 16.2 | V12: =ABS($Q$10-F4) -> 135.7
A13: Decision | B13: Fail to reject the null | H13: Burger | I13: 7 | J13: 11265.1 | K13: 1609.3 | L13: 244284.44 | S13: =ABS($N$10-C5) -> 1119.1 | T13: =ABS($O$10-D5) -> 1548.5 | U13: =ABS($P$10-E5) -> 0 | V13: =ABS($Q$10-F5) -> 0
A14: Conclusion relative to the problem | B14: Ther is no significant evidence to suggest a difference in the variation of sales among the food product types. | H14: Chicken | I14: 7 | J14: 9800 | K14: 1400 | L14: 513811.8 | S14: =ABS($N$10-C6) -> 70.9 | T14: =ABS($O$10-D6) -> 324 | U14: =ABS($P$10-E6) -> 26 | V14: =ABS($Q$10-F6) -> 252.3
A15: Part C. | H15: Sandwich | I15: 7 | J15: 8409.6 | K15: 1201.3714 | L15: 753911.22 | S15: =ABS($N$10-C7) -> 715.1 | T15: =ABS($O$10-D7) -> 429.8 | U15: =ABS($P$10-E7) -> 1504.8 | V15: =ABS($Q$10-F7) -> 437.3
A16: Select the most appropriate answers: | B16: No violation | H16: Snack | I16: 7 | J16: 7476.6 | K16: 1068.0857 | L16: 559596.34 | S16: =ABS($N$10-C8) -> 112.7 | T16: =ABS($O$10-D8) -> 356 | U16: =ABS($P$10-E8) -> 1570 | V16: =ABS($Q$10-F8) -> 1692.3
B17: valid
A18: Part D
A19: If Appropriate, Highlight the food type that differ in mean sales | B19: Burger | H19: ANOVA | S19: Anova: Single Factor
B20: Chicken | H20: Source of Variation | I20: SS | J20: df | K20: MS | L20: F | M20: P-value | N20: F crit
B21: Sandwich | H21: Between Groups | I21: 1173393.5 | J21: 3 | K21: 391131.18 | L21: 0.75522391 | M21: 0.53017492 | N21: 3.0087866 | S21: SUMMARY
B22: Snack | H22: Within Groups | I22: 12429623 | J22: 24 | K22: 517900.95 | S22: Groups | T22: Count | U22: Sum | V22: Average | W22: Variance
S23: Burger | T23: 7 | U23: 2327.8 | V23: 332.54286 | W23: 176129.88
H24: Total | I24: 13603016 | J24: 27 | S24: Chicken | T24: 7 | U24: 3242.6 | V24: 463.22857 | W24: 275605.64
S25: Sandwich | T25: 7 | U25: 4057 | V25: 579.57143 | W25: 471531.7
S26: Snack | T26: 7 | U26: 3396.1 | V26: 485.15714 | W26: 329527.49
S29: ANOVA
S30: Source of Variation | T30: SS | U30: df | V30: MS | W30: F | X30: P-value | Y30: F crit
S31: Between Groups | T31: 217566.25 | U31: 3 | V31: 72522.083 | W31: 0.23155297 | X31: 0.87348952 | Y31: 3.0087866
S32: Within Groups | T32: 7516768.2 | U32: 24 | V32: 313198.68
S34: Total | T34: 7734334.5 | U34: 27

Sheet 11.3
A1: 11.3 | F1: Sunlight Exposure
A2: Parts A, B, & C | D2: Water Frequency | E2: None | F2: Low | G2: Med | H2: High
A3: Sunlight & Water Interaction? | B3: No | D3: Daily | E3: 4.8 | F3: 5 | G3: 6 | H3: 6.3
A4: P-value? | B4: =K46 -> 0.23394201 | D4: Daily | E4: 4.4 | F4: 5.2 | G4: 6.2 | H4: 6.4
A5: Sunlight? | B5: Yes | D5: Daily | E5: 3.2 | F5: 5.6 | G5: 4.7 | H5: 5.6
A6: P-value? | B6: =L45 -> 2.9011196 | D6: Daily | E6: 3.9 | F6: 4.3 | G6: 5.5 | H6: 4.8
A7: Water Frequency? | B7: No | D7: Daily | E7: 4.4 | F7: 4.8 | G7: 5.8 | H7: 5.8
A8: P-value? | B8: =K44 -> 0.92623266 | D8: Weekly | E8: 4.4 | F8: 4.9 | G8: 5.8 | H8: 6
A9: Part D | D9: Weekly | E9: 4.2 | F9: 5.3 | G9: 6.2 | H9: 4.9
B10: Place the plots below the data | D10: Weekly | E10: 3.8 | F10: 5.7 | G10: 6.3 | H10: 4.6
D11: Weekly | E11: 3.7 | F11: 5.4 | G11: 6.5 | H11: 5.6
D12: Weekly | E12: 3.9 | F12: 4.8 | G12: 5.5 | H12: 5.5
B13: =E2 -> None | C13: =AVERAGE(E3:E12) -> 4.07
B14: =F2 -> Low | C14: =AVERAGE(F3:F12) -> 5.1
B15: =G2 -> Med | C15: =AVERAGE(G3:G12) -> 5.85
B16: =H2 -> High | C16: =AVERAGE(H3:I12) -> 5.55
F20: Anova: Two-Factor With Replication
F22: SUMMARY | G22: None | H22: Low | I22: Med | J22: High | K22: Total
F23: Daily
F24: Count | G24: 5 | H24: 5 | I24: 5 | J24: 5 | K24: 20
F25: Sum | G25: 20.7 | H25: 24.9 | I25: 28.2 | J25: 28.9 | K25: 102.7
F26: Average | G26: 4.14 | H26: 4.98 | I26: 5.64 | J26: 5.78 | K26: 5.135
F27: Variance | G27: 0.378 | H27: 0.232 | I27: 0.343 | J27: 0.412 | K27: 0.73081579
F29: Weekly
F30: Count | G30: 5 | H30: 5 | I30: 5 | J30: 5 | K30: 20
F31: Sum | G31: 20 | H31: 26.1 | I31: 30.3 | J31: 26.6 | K31: 103
F32: Average | G32: 4 | H32: 5.22 | I32: 6.06 | J32: 5.32 | K32: 5.15
F33: Variance | G33: 0.085 | H33: 0.137 | I33: 0.163 | J33: 0.317 | K33: 0.72263158
F35: Total
F36: Count | G36: 10 | H36: 10 | I36: 10 | J36: 10
F37: Sum | G37: 40.7 | H37: 51 | I37: 58.5 | J37: 55.5
F38: Average | G38: 4.07 | H38: 5.1 | I38: 5.85 | J38: 5.55
F39: Variance | G39: 0.21122222 | H39: 0.18 | I39: 0.27388889 | J39: 0.38277778
F42: ANOVA
F43: Source of Variation | G43: SS | H43: df | I43: MS | J43: F | K43: P-value | L43: F crit
F44: Days (water) | G44: 0.00225 | H44: 1 | I44: 0.00225 | J44: 0.0087082729 | K44: 0.92623266 | L44: 4.1490974
F45: Sunlight | G45: 18.18675 | H45: 3 | I45: 6.06225 | J45: 23.46299 | K45: 3.2148436e-08 | L45: 2.9011196
F46: Interaction | G46: 1.16075 | H46: 3 | I46: 0.38691667 | J46: 1.4975004 | K46: 0.23394201 | L46: 2.9011196
F47: Within | G47: 8.268 | H47: 32 | I47: 0.258375
F49: Total | G49: 27.61775 | H49: 39

Sheet Paired
A1: Bookstore | B1: Online | C1: Di | E1: Paired t Test
A2: 200 | B2: 121.49 | C2: =A2-B2 -> 78.51
A3: 304 | B3: 235.88 | C3: =A3-B3 -> 68.12 | E3: Data
A4: 179.35 | B4: 107.61 | C4: =A4-B4 -> 71.74 | E4: Hypothesized Mean Diff. | F4: 0
A5: 72 | B5: 59.99 | C5: =A5-B5 -> 12.01 | E5: Level of Significance | F5: 0.05
A6: 277.15 | B6: 146.99 | C6: =A6-B6 -> 130.16
A7: 73.75 | B7: 63.49 | C7: =A7-B7 -> 10.26 | E7: Intermediate Calculations
A8: 171.65 | B8: 138.99 | C8: =A8-B8 -> 32.66 | E8: Sample Size | F8: =COUNT(A:$A) -> 16
A9: 65 | B9: 42.26 | C9: =A9-B9 -> 22.74 | E9: DBar | F9: =AVERAGE($C:$C) -> 42.60125
A10: 47.45 | B10: 65.99 | C10: =A10-B10 -> -18.54 | E10: degrees of freedom | F10: =F8 - 1 -> 15
A11: 106 | B11: 37.83 | C11: =A11-B11 -> 68.17 | E11: SD | F11: =SQRT(DEVSQ(C2:C17)/F10) -> 43.797044
A12: 55.95 | B12: 102.99 | C12: =A12-B12 -> -47.04 | E12: Standard Error | F12: =F11/SQRT(F8) -> 10.949261
A13: 224.4 | B13: 144.99 | C13: =A13-B13 -> 79.41 | E13: t Test Statistic | F13: =(F9 - F4)/F12 -> 3.8907877
A14: 223.2 | B14: 179.39 | C14: =A14-B14 -> 43.81
A15: 250.65 | B15: 191.49 | C15: =A15-B15 -> 59.16 | E15: Two-Tailed Test
A16: 34.95 | B16: 28.66 | C16: =A16-B16 -> 6.29 | E16: Lower Critical Value | F16: =-_xlfn.T.INV.2T(F5, F10) -> -2.1314495
A17: 172.65 | B17: 108.49 | C17: =A17-B17 -> 64.16 | E17: Upper Critical Value | F17: =_xlfn.T.INV.2T(F5, F10) -> 2.1314495
E18: p-Value | F18: =_xlfn.T.DIST.2T(ABS(F13), F10) -> 0.00144819
E19: =IF(F18 < F5, "Reject the null hypothesis", "Do not reject the null hypothesis") -> Reject the null hypothesis

Sheet Paired_Low
A1: Bookstore | B1: Online | C1: Di | E1: Paired t Test
A2: 200 | B2: 121.49 | C2: =A2-B2 -> 78.51
A3: 304 | B3: 235.88 | C3: =A3-B3 -> 68.12 | E3: Data
A4: 179.35 | B4: 107.61 | C4: =A4-B4 -> 71.74 | E4: Hypothesized Mean Diff. | F4: 0
A5: 72 | B5: 59.99 | C5: =A5-B5 -> 12.01 | E5: Level of significance | F5: 0.05
A6: 277.15 | B6: 146.99 | C6: =A6-B6 -> 130.16
A7: 73.75 | B7: 63.49 | C7: =A7-B7 -> 10.26 | E7: Intermediate Calculations
A8: 171.65 | B8: 138.99 | C8: =A8-B8 -> 32.66 | E8: Sample Size | F8: =COUNT(A:$A) -> 16
A9: 65 | B9: 42.26 | C9: =A9-B9 -> 22.74 | E9: DBar | F9: =AVERAGE($C:$C) -> 42.60125
A10: 47.45 | B10: 65.99 | C10: =A10-B10 -> -18.54 | E10: degrees of freedom | F10: =F8 - 1 -> 15
A11: 106 | B11: 37.83 | C11: =A11-B11 -> 68.17 | E11: SD | F11: =SQRT(DEVSQ(C:C)/F10) -> 43.797044
A12: 55.95 | B12: 102.99 | C12: =A12-B12 -> -47.04 | E12: Standard Error | F12: =F11/SQRT(F8) -> 10.949261
A13: 224.4 | B13: 144.99 | C13: =A13-B13 -> 79.41 | E13: t Test Statistic | F13: =(F9 - F4)/F12 -> 3.8907877
A14: 223.2 | B14: 179.39 | C14: =A14-B14 -> 43.81
A15: 250.65 | B15: 191.49 | C15: =A15-B15 -> 59.16 | E15: Lower-Tail Test | H15: One-Tail Calculations
A16: 34.95 | B16: 28.66 | C16: =A16-B16 -> 6.29 | E16: Lower Critical Value | F16: =-_xlfn.T.INV.2T(2 * F5, F10) -> -1.7530504 | H16: T.DIST.RT | I16: =_xlfn.T.DIST.RT(ABS(F13), F10) -> 0.00072409499
A17: 172.65 | B17: 108.49 | C17: =A17-B17 -> 64.16 | E17: p-Value | F17: =IF(F13 < 0, I16, I17) -> 0.99927591 | H17: 1 - T.DIST.RT | I17: =1 - I16 -> 0.99927591
E18: =IF(F17< F5, "Reject the null hypothesis", "Do not reject the null hypothesis") -> Do not reject the null hypothesis

Sheet Paired_Upper
A1: Bookstore | B1: Online | C1: Di | E1: Paired t Test
A2: 200 | B2: 121.49 | C2: =A2-B2 -> 78.51
A3: 304 | B3: 235.88 | C3: =A3-B3 -> 68.12 | E3: Data
A4: 179.35 | B4: 107.61 | C4: =A4-B4 -> 71.74 | E4: Hypothesized Mean Diff. | F4: 0
A5: 72 | B5: 59.99 | C5: =A5-B5 -> 12.01 | E5: Level of significance | F5: 0.05
A6: 277.15 | B6: 146.99 | C6: =A6-B6 -> 130.16
A7: 73.75 | B7: 63.49 | C7: =A7-B7 -> 10.26 | E7: Intermediate Calculations
A8: 171.65 | B8: 138.99 | C8: =A8-B8 -> 32.66 | E8: Sample Size | F8: =COUNT(A:$A) -> 16
A9: 65 | B9: 42.26 | C9: =A9-B9 -> 22.74 | E9: DBar | F9: =AVERAGE($C:$C) -> 42.60125
A10: 47.45 | B10: 65.99 | C10: =A10-B10 -> -18.54 | E10: degrees of freedom | F10: =F8 - 1 -> 15
A11: 106 | B11: 37.83 | C11: =A11-B11 -> 68.17 | E11: SD | F11: =SQRT(DEVSQ(C:C)/F10) -> 43.797044
A12: 55.95 | B12: 102.99 | C12: =A12-B12 -> -47.04 | E12: Standard Error | F12: =F11/SQRT(F8) -> 10.949261
A13: 224.4 | B13: 144.99 | C13: =A13-B13 -> 79.41 | E13: t Test Statistic | F13: =(F9 - F4)/F12 -> 3.8907877
A14: 223.2 | B14: 179.39 | C14: =A14-B14 -> 43.81
A15: 250.65 | B15: 191.49 | C15: =A15-B15 -> 59.16 | E15: Upper-Tail Test | H15: One-Tail Calculations
A16: 34.95 | B16: 28.66 | C16: =A16-B16 -> 6.29 | E16: Upper Critical Value | F16: =_xlfn.T.INV.2T(2 * F5, F10) -> 1.7530504 | H16: T.DIST.RT | I16: =_xlfn.T.DIST.RT(ABS(F13), F10) -> 0.00072409499
A17: 172.65 | B17: 108.49 | C17: =A17-B17 -> 64.16 | E17: p-Value | F17: =IF(F13 < 0,I17,I16) -> 0.00072409499 | H17: 1 - T.DIST.RT | I17: =1 - I16 -> 0.99927591
E18: =IF(F17 < F5, "Reject the null hypothesis", "Do not reject the null hypothesis") -> Reject the null hypothesis

Sheet Pooled
A1: Special Front | B1: In-Aisle | D1: Pooled-Variance t Test for Differences in Two Means
A2: 224 | B2: 192 | D2: (assumes equal population variances)
A3: 189 | B3: 236 | D3: Data | G3: Confidence Interval Estimate
A4: 248 | B4: 164 | D4: Hypothesized Difference | E4: 0 | G4: for the Difference Between Two Means
A5: 285 | B5: 154 | D5: Level of Significance | E5: 0.05
A6: 273 | B6: 189 | D6: Population 1 Sample | G6: Data
A7: 160 | B7: 220 | D7: Sample Size | E7: =COUNT($A:$A) -> 10 | G7: Confidence Level | H7: 0.95
A8: 243 | B8: 261 | D8: Sample Mean | E8: =AVERAGE($A:$A) -> 243.4
A9: 215 | B9: 186 | D9: Sample Standard Deviation | E9: =_xlfn.STDEV.S($A:$A) -> 47.705579 | G9: Intermediate Calculations
A10: 280 | B10: 219 | D10: Population 2 Sample | G10: Degrees of Freedom | H10: =E16 + E17 -> 18
A11: 317 | B11: 202 | D11: Sample Size | E11: =COUNT($B:$B) -> 10 | G11: t Value | H11: =_xlfn.T.INV.2T(1 - H7, H10) -> 2.100922
D12: Sample Mean | E12: =AVERAGE($B:$B) -> 202.3 | G12: Interval Half Width | H12: =(H11 * SQRT(E19 * (1/E7 + 1/E11))) -> 38.36029
D13: Sample Standard Deviation | E13: =_xlfn.STDEV.S($B:$B) -> 32.527083
G14: Confidence Interval
D15: Intermediate Calculations | G15: Interval Lower Limit | H15: =E21 - H12 -> 2.7397102
D16: Population 1 Sample Degrees of Freedom | E16: =E7 - 1 -> 9 | G16: Interval Upper Limit | H16: =E21 + H12 -> 79.46029
D17: Population 2 Sample Degrees of Freedom | E17: =E11 - 1 -> 9
D18: Total Degrees of Freedom | E18: =E16 + E17 -> 18
D19: Pooled Variance | E19: =((E16 * E9^2) + (E17 * E13^2))/E18 -> 1666.9167
D20: Standard Error | E20: =SQRT(E19 * (1/E7 + 1/E11)) -> 18.258788
D21: Difference in Sample Means | E21: =E8 - E12 -> 41.1
D22: t Test Statistic | E22: =(E21 - E4)/E20 -> 2.2509709
D24: Two-Tail Test
D25: Lower Critical Value | E25: =-(_xlfn.T.INV.2T(E5, E18)) -> -2.100922
D26: Upper Critical Value | E26: =_xlfn.T.INV.2T(E5, E18) -> 2.100922
D27: p-Value | E27: =_xlfn.T.DIST.2T(ABS(E22), E18) -> 0.037122714
D28: =IF(E27 < E5, "Reject the null hypothesis", "Do not reject the null hypothesis") -> Reject the null hypothesis

Sheet Pooled_LOWER
A1: Special Front | B1: In-Aisle | D1: Pooled-Variance t Test for Differences in Two Means
A2: 224 | B2: 192 | D2: (assumes equal population variances)
A3: 189 | B3: 236 | D3: Data | G3: Confidence Interval Estimate
A4: 248 | B4: 164 | D4: Hypothesized Difference | E4: 0 | G4: for the Difference Between Two Means
A5: 285 | B5: 154 | D5: Level of Significance | E5: 0.05
A6: 273 | B6: 189 | D6: Population 1 Sample | G6: Data
A7: 160 | B7: 220 | D7: Sample Size | E7: =COUNT($A:$A) -> 10 | G7: Confidence Level | H7: 0.95
A8: 243 | B8: 261 | D8: Sample Mean | E8: =AVERAGE($A:$A) -> 243.4
A9: 215 | B9: 186 | D9: Sample Standard Deviation | E9: =_xlfn.STDEV.S($A:$A) -> 47.705579 | G9: Intermediate Calculations
A10: 280 | B10: 219 | D10: Population 2 Sample | G10: Degrees of Freedom | H10: =E16 + E17 -> 18
A11: 317 | B11: 202 | D11: Sample Size | E11: =COUNT($B:$B) -> 10 | G11: t Value | H11: =_xlfn.T.INV.2T(1 - H7, H10) -> 2.100922
D12: Sample Mean | E12: =AVERAGE($B:$B) -> 202.3 | G12: Interval Half Width | H12: =(H11 * SQRT(E19 * (1/E7 + 1/E11))) -> 38.36029
D13: Sample Standard Deviation | E13: =_xlfn.STDEV.S($B:$B) -> 32.527083
G14: Confidence Interval
D15: Intermediate Calculations | G15: Interval Lower Limit | H15: =E21 - H12 -> 2.7397102
D16: Population 1 Sample Degrees of Freedom | E16: =E7 - 1 -> 9 | G16: Interval Upper Limit | H16: =E21 + H12 -> 79.46029
D17: Population 2 Sample Degrees of Freedom | E17: =E11 - 1 -> 9
D18: Total Degrees of Freedom | E18: =E16 + E17 -> 18
D19: Pooled Variance | E19: =((E16 * E9^2) + (E17 * E13^2))/E18 -> 1666.9167
D20: Standard Error | E20: =SQRT(E19 * (1/E7 + 1/E11)) -> 18.258788
D21: Difference in Sample Means | E21: =E8 - E12 -> 41.1
D22: t Test Statistic | E22: =(E21 - E4)/E20 -> 2.2509709
D24: Lower-Tail Test | G24: One-Tail Calculations
D25: Lower Critical Value | E25: =-(_xlfn.T.INV.2T(2*E5, E18)) -> -1.7340636 | G25: T.DIST.RT value | H25: =_xlfn.T.DIST.RT(ABS(E22), E18) -> 0.018561357
D26: p-Value | E26: =IF(E22 < 0, H25, H26) -> 0.98143864 | G26: 1 - T.DIST.RT value | H26: =1 - H25 -> 0.98143864
D27: =IF(E26 < E5, "Reject the null hypothesis", "Do not reject the null hypothesis") -> Do not reject the null hypothesis

Sheet Pooled_UPPER
A1: Special Front | B1: In-Aisle | D1: Pooled-Variance t Test for Differences in Two Means
A2: 224 | B2: 192 | D2: (assumes equal population variances)
A3: 189 | B3: 236 | D3: Data | G3: Confidence Interval Estimate
A4: 248 | B4: 164 | D4: Hypothesized Difference | E4: 0 | G4: for the Difference Between Two Means
A5: 285 | B5: 154 | D5: Level of Significance | E5: 0.05
A6: 273 | B6: 189 | D6: Population 1 Sample | G6: Data
A7: 160 | B7: 220 | D7: Sample Size | E7: =COUNT($A:$A) -> 10 | G7: Confidence Level | H7: 0.95
A8: 243 | B8: 261 | D8: Sample Mean | E8: =AVERAGE($A:$A) -> 243.4
A9: 215 | B9: 186 | D9: Sample Standard Deviation | E9: =_xlfn.STDEV.S($A:$A) -> 47.705579 | G9: Intermediate Calculations
A10: 280 | B10: 219 | D10: Population 2 Sample | G10: Degrees of Freedom | H10: =E16 + E17 -> 18
A11: 317 | B11: 202 | D11: Sample Size | E11: =COUNT($B:$B) -> 10 | G11: t Value | H11: =_xlfn.T.INV.2T(1 - H7, H10) -> 2.100922
D12: Sample Mean | E12: =AVERAGE($B:$B) -> 202.3 | G12: Interval Half Width | H12: =(H11 * SQRT(E19 * (1/E7 + 1/E11))) -> 38.36029
D13: Sample Standard Deviation | E13: =_xlfn.STDEV.S($B:$B) -> 32.527083
G14: Confidence Interval
D15: Intermediate Calculations | G15: Interval Lower Limit | H15: =E21 - H12 -> 2.7397102
D16: Population 1 Sample Degrees of Freedom | E16: =E7 - 1 -> 9 | G16: Interval Upper Limit | H16: =E21 + H12 -> 79.46029
D17: Population 2 Sample Degrees of Freedom | E17: =E11 - 1 -> 9
D18: Total Degrees of Freedom | E18: =E16 + E17 -> 18
D19: Pooled Variance | E19: =((E16 * E9^2) + (E17 * E13^2))/E18 -> 1666.9167
D20: Standard Error | E20: =SQRT(E19 * (1/E7 + 1/E11)) -> 18.258788
D21: Difference in Sample Means | E21: =E8 - E12 -> 41.1
D22: t Test Statistic | E22: =(E21 - E4)/E20 -> 2.2509709
D24: Upper-Tail Test | G24: One-Tail Calculations
D25: Upper Critical Value | E25: =(_xlfn.T.INV.2T(2*E5,E18)) -> 1.7340636 | G25: T.DIST.RT value | H25: =_xlfn.T.DIST.RT(ABS(E22), E18) -> 0.018561357
D26: p-Value | E26: =IF(E22 < 0, H26, H25) -> 0.018561357 | G26: 1 - T.DIST.RT value | H26: =1 - H25 -> 0.98143864
D27: =IF(E26 < E5,"Reject the null hypothesis","Do not reject the null hypothesis") -> Reject the null hypothesis

Sheet Separate_Var
A1: Special Front | B1: In-Aisle | D1: Separate-Variances t Test
A2: 224 | B2: 192 | D2: (assumes unequal population variances)
A3: 189 | B3: 236 | D3: Data
A4: 248 | B4: 164 | D4: Hypothesized Difference | E4: 0
A5: 285 | B5: 154 | D5: Level of Significance | E5: 0.05
A6: 273 | B6: 189 | D6: Population 1 Sample
A7: 160 | B7: 220 | D7: Sample Size | E7: =COUNT($A:$A) -> 10
A8: 243 | B8: 261 | D8: Sample Mean | E8: =AVERAGE($A:$A) -> 243.4
A9: 215 | B9: 186 | D9: Sample Standard Deviation | E9: =STDEV($A:$A) -> 47.705579
A10: 280 | B10: 219 | D10: Sample Variance | E10: =E9^2 -> 2275.8222
A11: 317 | B11: 202 | D11: Population 2 Sample
D12: Sample Size | E12: =COUNT($B:$B) -> 10
D13: Sample Mean | E13: =AVERAGE(B2:B11) -> 202.3
D14: Sample Standard Deviation | E14: =STDEV($B:$B) -> 32.527083
D15: Sample Variance | E15: =E14^2 -> 1058.0111
D17: Intermediate Calculations
D18: Degrees of Freedom | E18: =INT(((E10/E7+E15/E12)^2)/((E10/E7)^2/(E7-1)+(E15/E12)^2/(E12-1))) -> 15
D19: Separate-Variance t Test Statistic | E19: =(E8-E13)/SQRT(E10/E7 + E15/E12) -> 2.2509709
D21: Two-Tail Test
D22: Lower Critical Value | E22: =-(_xlfn.T.INV.2T(E5, E18)) -> -2.1314495
D23: Upper Critical Value | E23: =_xlfn.T.INV.2T(E5, E18) -> 2.1314495
D24: p-Value | E24: =_xlfn.T.DIST.2T(ABS(E19),E18) - E4 -> 0.039813679
D25: =IF(E24 < E5,"Reject the null hypothesis","Do not reject the null hypothesis") -> Reject the null hypothesis

Sheet Separate_Low
A1: Special Front | B1: In-Aisle | D1: Separate-Variances t Test
A2: 224 | B2: 192 | D2: (assumes unequal population variances)
A3: 189 | B3: 236 | D3: Data
A4: 248 | B4: 164 | D4: Hypothesized Difference | E4: 0
A5: 285 | B5: 154 | D5: Level of Significance | E5: 0.05
A6: 273 | B6: 189 | D6: Population 1 Sample
A7: 160 | B7: 220 | D7: Sample Size | E7: =COUNT($A:$A) -> 10
A8: 243 | B8: 261 | D8: Sample Mean | E8: =AVERAGE($A:$A) -> 243.4
A9: 215 | B9: 186 | D9: Sample Standard Deviation | E9: =STDEV($A:$A) -> 47.705579
A10: 280 | B10: 219 | D10: Sample Variance | E10: =E9^2 -> 2275.8222
A11: 317 | B11: 202 | D11: Population 2 Sample
D12: Sample Size | E12: =COUNT($B:$B) -> 10
D13: Sample Mean | E13: =AVERAGE($B:$B) -> 202.3
D14: Sample Standard Deviation | E14: =STDEV($B:$B) -> 32.527083
D15: Sample Variance | E15: =E14^2 -> 1058.0111
D17: Intermediate Calculations
D18: Degrees of Freedom | E18: =INT(((E10/E7+E15/E12)^2)/((E10/E7)^2/(E7-1)+(E15/E12)^2/(E12-1))) -> 15
D19: Separate-Variance t Test Statistic | E19: =(E8-E13)/SQRT(E10/E7 + E15/E12) -> 2.2509709
D21: Lower-Tail Test
D22: Lower Critical Value | E22: =-(_xlfn.T.INV.2T(2*E5,E18)) -> -1.7530504
D23: p-Value | E23: =IF(E20<0,_xlfn.T.DIST.RT(ABS(E19),E18),1-_xlfn.T.DIST.RT(ABS(E19),E18)) -> 0.98009316
D24: =IF(E23 < E5,"Reject the null hypothesis","Do not reject the null hypothesis") -> Do not reject the null hypothesis

Sheet Separate_upper
A1: Special Front | B1: In-Aisle | D1: Separate-Variances t Test
A2: 224 | B2: 192 | D2: (assumes unequal population variances)
A3: 189 | B3: 236 | D3: Data
A4: 248 | B4: 164 | D4: Hypothesized Difference | E4: 0
A5: 285 | B5: 154 | D5: Level of Significance | E5: 0.05
A6: 273 | B6: 189 | D6: Population 1 Sample
A7: 160 | B7: 220 | D7: Sample Size | E7: =COUNT($A:$A) -> 10
A8: 243 | B8: 261 | D8: Sample Mean | E8: =AVERAGE($A:$A) -> 243.4
A9: 215 | B9: 186 | D9: Sample Standard Deviation | E9: =STDEV($A:$A) -> 47.705579
A10: 280 | B10: 219 | D10: Sample Variance | E10: =E9^2 -> 2275.8222
A11: 317 | B11: 202 | D11: Population 2 Sample
D12: Sample Size | E12: =COUNT($B:$B) -> 10
D13: Sample Mean | E13: =AVERAGE([1]DataCopy!$B:$B) -> 202.3
D14: Sample Standard Deviation | E14: =STDEV($B:$B) -> 32.527083
D15: Sample Variance | E15: =E14^2 -> 1058.0111
D17: Intermediate Calculations
D18: Degrees of Freedom | E18: =INT(((E10/E7+E15/E12)^2)/((E10/E7)^2/(E7-1)+(E15/E12)^2/(E12-1))) -> 15
D19: Separate-Variance t Test Statistic | E19: =(E8-E13)/SQRT(E10/E7 + E15/E12) -> 2.2509709
D21: Upper-Tail Test
D22: Upper Critical Value | E22: =(_xlfn.T.INV.2T(2*E5,E18)) -> 1.7530504
D23: p-Value | E23: =IF(E19<0,_xlfn.T.DIST.RT(ABS(E19),E18),1-_xlfn.T.DIST.RT(ABS(E19),E18)) -> 0.98009316
D24: =IF(E23 < E5,"Reject the null hypothesis","Do not reject the null hypothesis") -> Do not reject the null hypothesis

Sheet Z two Prop
A1: Z Test for Differences in Two Proportions
A3: Data | D3: Confidence Interval Estimate
A4: Hypothesized Difference | B4: 0 | D4: for the Difference Between Two Proportions
A5: Level of Significance | B5: 0.05
A6: Group 1 | D6: Data
A7: Number of Items of Interest | B7: 163 | D7: Confidence Level | E7: 0.95
A8: Sample Size | B8: 227
A9: Group 2 | D9: Intermediate Calculations
A10: Number of Items of Interest | B10: 154 | D10: Z Value | E10: =_xlfn.NORM.S.INV((1 - E7)/2) -> -1.959964
A11: Sample Size | B11: 262 | D11: Std. Error of the Diff. Between Two Proportions | E11: =SQRT((B14*(1 - B14)/B8) + (B15 * (1 - B15)/B11)) -> 0.042621953
D12: Interval Half Width | E12: =ABS(E10 * E11) -> 0.083537494
A13: Intermediate Calculations
A14: Group 1 Proportion | B14: =B7/B8 -> 0.71806167 | D14: Confidence Interval
A15: Group 2 Proportion | B15: =B10/B11 -> 0.58778626 | D15: Interval Lower Limit | E15: =B16 - E12 -> 0.046737921
A16: Difference in Two Proportions | B16: =B14 - B15 -> 0.13027541 | D16: Interval Upper Limit | E16: =B16 + E12 -> 0.21381291
A17: Average Proportion | B17: =(B7 + B10)/(B8 + B11) -> 0.64826176
A18: Z Test Statistic | B18: =(B16 - B4)/SQRT(B17 * (1 - B17) * (1/B8 + 1/B11)) -> 3.0087535
A20: Two-Tail Test
A21: Lower Critical Value | B21: =_xlfn.NORM.S.INV(B5/2) -> -1.959964
A22: Upper Critical Value | B22: =_xlfn.NORM.S.INV(1 - B5/2) -> 1.959964
A23: p-Value | B23: =2 * (1 - _xlfn.NORM.S.DIST(ABS(B18), TRUE)) -> 0.0026232183
A24: =IF(B23 < B5, "Reject the null hypothesis", "Do not reject the null hypothesis") -> Reject the null hypothesis

Sheet Z_2_Prop_LOWER
A1: Z Test for Differences in Two Proportions
A3: Data | D3: Confidence Interval Estimate
A4: Hypothesized Difference | B4: 0 | D4: for the Difference Between Two Proportions
A5: Level of Significance | B5: 0.05
A6: Group 1 | D6: Data
A7: Number of Items of Interest | B7: 163 | D7: Confidence Level | E7: 0.95
A8: Sample Size | B8: 227
A9: Group 2 | D9: Intermediate Calculations
A10: Number of Items of Interest | B10: 154 | D10: Z Value | E10: =_xlfn.NORM.S.INV((1 - E7)/2) -> -1.959964
A11: Sample Size | B11: 262 | D11: Std. Error of the Diff. Between Two Proportions | E11: =SQRT((B14*(1 - B14)/B8) + (B15 * (1 - B15)/B11)) -> 0.042621953
D12: Interval Half Width | E12: =ABS(E10 * E11) -> 0.083537494
A13: Intermediate Calculations
A14: Group 1 Proportion | B14: =B7/B8 -> 0.71806167 | D14: Confidence Interval
A15: Group 2 Proportion | B15: =B10/B11 -> 0.58778626 | D15: Interval Lower Limit | E15: =B16 - E12 -> 0.046737921
A16: Difference in Two Proportions | B16: =B14 - B15 -> 0.13027541 | D16: Interval Upper Limit | E16: =B16 + E12 -> 0.21381291
A17: Average Proportion | B17: =(B7 + B10)/(B8 + B11) -> 0.64826176
A18: Z Test Statistic | B18: =(B16 - B4)/SQRT(B17 * (1 - B17) * (1/B8 + 1/B11)) -> 3.0087535
A20: Lower-Tail Test
A21: Lower Critical Value | B21: =_xlfn.NORM.S.INV(B5) -> -1.6448536
A22: p-Value | B22: =_xlfn.NORM.S.DIST(B18, TRUE) -> 0.99868839
A23: =IF(B22< B5, "Reject the null hypothesis", "Do not reject the null hypothesis") -> Do not reject the null hypothesis

Sheet Z_2_Prop
A1: Z Test for Differences in Two Proportions
A3: Data | D3: Confidence Interval Estimate
A4: Hypothesized Difference | B4: 0 | D4: for the Difference Between Two Proportions
A5: Level of Significance | B5: 0.05
A6: Group 1 | D6: Data
A7: Number of Items of Interest | B7: 163 | D7: Confidence Level | E7: 0.95
A8: Sample Size | B8: 227
A9: Group 2 | D9: Intermediate Calculations
A10: Number of Items of Interest | B10: 154 | D10: Z Value | E10: =_xlfn.NORM.S.INV((1 - E7)/2) -> -1.959964
A11: Sample Size | B11: 262 | D11: Std. Error of the Diff. Between Two Proportions | E11: =SQRT((B14*(1 - B14)/B8) + (B15 * (1 - B15)/B11)) -> 0.042621953
D12: Interval Half Width | E12: =ABS(E10 * E11) -> 0.083537494
A13: Intermediate Calculations
A14: Group 1 Proportion | B14: =B7/B8 -> 0.71806167 | D14: Confidence Interval
A15: Group 2 Proportion | B15: =B10/B11 -> 0.58778626 | D15: Interval Lower Limit | E15: =B16 - E12 -> 0.046737921
A16: Difference in Two Proportions | B16: =B14 - B15 -> 0.13027541 | D16: Interval Upper Limit | E16: =B16 + E12 -> 0.21381291
A17: Average Proportion | B17: =(B7 + B10)/(B8 + B11) -> 0.64826176
A18: Z Test Statistic | B18: =(B16 - B4)/SQRT(B17 * (1 - B17) * (1/B8 + 1/B11)) -> 3.0087535
A20: Upper-Tail Test
A21: Upper Critical Value | B21: =_xlfn.NORM.S.INV(1 - B5) -> 1.6448536
A22: p-Value | B22: =1 - _xlfn.NORM.S.DIST(B18, TRUE) -> 0.0013116092
A23: =IF(B22< B5, "Reject the null hypothesis", "Do not reject the null hypothesis") -> Reject the null hypothesis

Sheet F Two Vars
A1: Front of Store | B1: In-Aisle | D1: F Test for Differences in Two Variances
A2: 224 | B2: 192
A3: 189 | B3: 236 | D3: Data
A4: 248 | B4: 164 | D4: Level of Significance | E4: 0.05
A5: 285 | B5: 154 | D5: Larger-Variance Sample
A6: 273 | B6: 189 | D6: Sample Size | E6: =COUNT($A:$A) -> 10
A7: 160 | B7: 220 | D7: Sample Variance | E7: =_xlfn.VAR.S($A:$A) -> 2275.8222
A8: 243 | B8: 261 | D8: Smaller-Variance Sample
A9: 215 | B9: 186 | D9: Sample Size | E9: =COUNT($B:$B) -> 10
A10: 280 | B10: 219 | D10: Sample Variance | E10: =_xlfn.VAR.S($B:$B) -> 1058.0111
A11: 317 | B11: 202
D12: Intermediate Calculations
D13: F Test Statistic | E13: =E7/E10 -> 2.1510381
D14: Population 1 Sample Degrees of Freedom | E14: =E6 - 1 -> 9
D15: Population 2 Sample Degrees of Freedom | E15: =E9 - 1 -> 9
D17: Two-Tail Test
D18: Upper Critical Value | E18: =_xlfn.F.INV.RT(E4/2, E14, E15) -> 4.0259942
D19: p-Value | E19: =2 * _xlfn.F.DIST.RT(E13, E14, E15) -> 0.26930173
D20: =IF(E19 < E4, "Reject the null hypothesis","Do not reject the null hypothesis") -> Do not reject the null hypothesis

Sheet F Two Vars Upper
A1: Front of Store | B1: In-Aisle | D1: F Test for Differences in Two Variances
A2: 224 | B2: 192
A3: 189 | B3: 236 | D3: Data
A4: 248 | B4: 164 | D4: Level of Significance | E4: 0.05
A5: 285 | B5: 154 | D5: Larger-Variance Sample
A6: 273 | B6: 189 | D6: Sample Size | E6: =COUNT($A:$A) -> 10
A7: 160 | B7: 220 | D7: Sample Variance | E7: =_xlfn.VAR.S($A:$A) -> 2275.8222
A8: 243 | B8: 261 | D8: Smaller-Variance Sample
A9: 215 | B9: 186 | D9: Sample Size | E9: =COUNT($B:$B) -> 10
A10: 280 | B10: 219 | D10: Sample Variance | E10: =_xlfn.VAR.S($B:$B) -> 1058.0111
A11: 317 | B11: 202
D12: Intermediate Calculations
D13: F Test Statistic | E13: =E7/E10 -> 2.1510381
D14: Population 1 Sample Degrees of Freedom | E14: =E6 - 1 -> 9
D15: Population 2 Sample Degrees of Freedom | E15: =E9 - 1 -> 9
D17: Upper-Tail Test
D18: Upper Critical Value | E18: =_xlfn.F.INV.RT(E4, E14, E15) -> 3.1788931
D19: p-Value | E19: =_xlfn.F.DIST.RT(E13, E14, E15) -> 0.13465086
D20: =IF(E19 < E4, "Reject the null hypothesis","Do not reject the null hypothesis") -> Do not reject the null hypothesis

Sheet Levene's DATA
A1: In-aisle | B1: Front | C1: Kiosk | D1: Expert
A2: 30.06 | B2: 32.22 | C2: 30.78 | D2: 30.33
A3: 29.96 | B3: 31.47 | C3: 30.91 | D3: 30.29
A4: 30.19 | B4: 32.13 | C4: 30.79 | D4: 30.25
A5: 29.96 | B5: 31.86 | C5: 30.95 | D5: 30.25
A6: 29.74 | B6: 32.29 | C6: 31.13 | D6: 30.55
A7: Medians:
A8: =MEDIAN(A2:A6) -> 29.96 | B8: =MEDIAN(B2:B6) -> 32.13 | C8: =MEDIAN(C2:C6) -> 30.91 | D8: =MEDIAN(D2:D6) -> 30.29

Sheet Levene's AbsDiffs
A1: AbsDiff1 | B1: AbsDiff2 | C1: AbsDiff3 | D1: AbsDiff4
A2: =ABS('Levene''s DATA'!A2 - 'Levene''s DATA'!A$8) -> 0.1 | B2: =ABS('Levene''s DATA'!B2 - 'Levene''s DATA'!B$8) -> 0.09 | C2: =ABS('Levene''s DATA'!C2 - 'Levene''s DATA'!C$8) -> 0.13 | D2: =ABS('Levene''s DATA'!D2 - 'Levene''s DATA'!D$8) -> 0.04
A3: =ABS('Levene''s DATA'!A3 - 'Levene''s DATA'!A$8) -> 0 | B3: =ABS('Levene''s DATA'!B3 - 'Levene''s DATA'!B$8) -> 0.66 | C3: =ABS('Levene''s DATA'!C3 - 'Levene''s DATA'!C$8) -> 0 | D3: =ABS('Levene''s DATA'!D3 - 'Levene''s DATA'!D$8) -> 0
A4: =ABS('Levene''s DATA'!A4 - 'Levene''s DATA'!A$8) -> 0.23 | B4: =ABS('Levene''s DATA'!B4 - 'Levene''s DATA'!B$8) -> 0 | C4: =ABS('Levene''s DATA'!C4 - 'Levene''s DATA'!C$8) -> 0.12 | D4: =ABS('Levene''s DATA'!D4 - 'Levene''s DATA'!D$8) -> 0.04
A5: =ABS('Levene''s DATA'!A5 - 'Levene''s DATA'!A$8) -> 0 | B5: =ABS('Levene''s DATA'!B5 - 'Levene''s DATA'!B$8) -> 0.27 | C5: =ABS('Levene''s DATA'!C5 - 'Levene''s DATA'!C$8) -> 0.04 | D5: =ABS('Levene''s DATA'!D5 - 'Levene''s DATA'!D$8) -> 0.04
A6: =ABS('Levene''s DATA'!A6 - 'Levene''s DATA'!A$8) -> 0.22 | B6: =ABS('Levene''s DATA'!B6 - 'Levene''s DATA'!B$8) -> 0.16 | C6: =ABS('Levene''s DATA'!C6 - 'Levene''s DATA'!C$8) -> 0.22 | D6: =ABS('Levene''s DATA'!D6 - 'Levene''s DATA'!D$8) -> 0.26

Sheet Levene's
A1: ANOVA: Levene Test | I1: Calculations
I2: c | J2: =COUNTA('Levene''s AbsDiffs'!$1:$1) -> 4
A3: SUMMARY | I3: n | J3: =SUM(B5:B8) -> 20
A4: Groups | B4: Count | C4: Sum | D4: Average | E4: Variance
A5: ='Levene''s DATA'!A1 -> In-aisle | B5: =COUNT('Levene''s AbsDiffs'!$A:$A) -> 5 | C5: =SUM('Levene''s AbsDiffs'!$A:$A) -> 0.55 | D5: =AVERAGE('Levene''s AbsDiffs'!$A:$A) -> 0.11 | E5: =_xlfn.VAR.S('Levene''s AbsDiffs'!$A:$A) -> 0.0127
A6: ='Levene''s DATA'!B1 -> Front | B6: =COUNT('Levene''s AbsDiffs'!$B:$B) -> 5 | C6: =SUM('Levene''s AbsDiffs'!$B:$B) -> 1.18 | D6: =AVERAGE('Levene''s AbsDiffs'!$B:$B) -> 0.236 | E6: =_xlfn.VAR.S('Levene''s AbsDiffs'!$B:$B) -> 0.06593
A7: ='Levene''s DATA'!C1 -> Kiosk | B7: =COUNT('Levene''s AbsDiffs'!$C:$C) -> 5 | C7: =SUM('Levene''s AbsDiffs'!$C:$C) -> 0.51 | D7: =AVERAGE('Levene''s AbsDiffs'!$C:$C) -> 0.102 | E7: =_xlfn.VAR.S('Levene''s AbsDiffs'!$C:$C) -> 0.00732
A8: ='Levene''s DATA'!D1 -> Expert | B8: =COUNT('Levene''s AbsDiffs'!$D:$D) -> 5 | C8: =SUM('Levene''s AbsDiffs'!$D:$D) -> 0.38 | D8: =AVERAGE('Levene''s AbsDiffs'!$D:$D) -> 0.076 | E8: =_xlfn.VAR.S('Levene''s AbsDiffs'!$D:$D) -> 0.01088
A11: ANOVA
A12: Source of Variation | B12: SS | C12: df | D12: MS | E12: F | F12: P - value | G12: F crit
A13: Between Groups | B13: =B16 - DEVSQ('Levene''s AbsDiffs'!$A:$A) - DEVSQ('Levene''s AbsDiffs'!$B:$B) - DEVSQ('Levene''s AbsDiffs'!$C:$C) - DEVSQ('Levene''s AbsDiffs'!$D:$D) -> 0.07666 | C13: =J2 - 1 -> 3 | D13: =B13/C13 -> 0.025553333 | E13: =D13/D14 -> 1.0555957 | F13: =_xlfn.F.DIST.RT(E13, C13, C14) -> 0.39532418 | G13: =_xlfn.F.INV.RT(0.05, C13, C14) -> 3.2388715
A14: Within Groups | B14: =B16 - B13 -> 0.38732 | C14: =J3 - J2 -> 16 | D14: =B14/C14 -> 0.0242075
A16: Total | B16: =DEVSQ('Levene''s AbsDiffs'!$A$1:$D$6) -> 0.46398 | C16: =C13+C14 -> 19
E17: Level of significance | G17: 0.05

Sheet ASFData
A1: In-aisle | B1: Front | C1: Kiosk | D1: Expert
A2: 30.06 | B2: 32.22 | C2: 30.78 | D2: 30.33
A3: 29.96 | B3: 31.47 | C3: 30.91 | D3: 30.29
A4: 30.19 | B4: 32.13 | C4: 30.79 | D4: 30.25
A5: 29.96 | B5: 31.86 | C5: 30.95 | D5: 30.25
A6: 29.74 | B6: 32.29 | C6: 31.13 | D6: 30.55

Sheet One Way Anova
A1: One-Way ANOVA (ANOVA: Single Factor) | I1: Calculations
I2: c | J2: =COUNTA(ASFData!$1:$1) -> 4
A3: SUMMARY | I3: n | J3: =SUM(B5:B8) -> 20
A4: Groups | B4: Count | C4: Sum | D4: Average | E4: Variance
A5: =ASFData!A1 -> In-aisle | B5: =COUNT(ASFData!$A:$A) -> 5 | C5: =SUM(ASFData!$A:$A) -> 149.91 | D5: =AVERAGE(ASFData!$A:$A) -> 29.982 | E5: =_xlfn.VAR.S(ASFData!$A:$A) -> 0.02722
A6: =ASFData!B1 -> Front | B6: =COUNT(ASFData!$B:$B) -> 5 | C6: =SUM(ASFData!$B:$B) -> 159.97 | D6: =AVERAGE(ASFData!$B:$B) -> 31.994 | E6: =_xlfn.VAR.S(ASFData!$B:$B) -> 0.11243
A7: =ASFData!C1 -> Kiosk | B7: =COUNT(ASFData!$C:$C) -> 5 | C7: =SUM(ASFData!$C:$C) -> 154.56 | D7: =AVERAGE(ASFData!$C:$C) -> 30.912 | E7: =_xlfn.VAR.S(ASFData!$C:$C) -> 0.02032
A8: =ASFData!D1 -> Expert | B8: =COUNT(ASFData!$D:$D) -> 5 | C8: =SUM(ASFData!$D:$D) -> 151.67 | D8: =AVERAGE(ASFData!$D:$D) -> 30.334 | E8: =_xlfn.VAR.S(ASFData!$D:$D) -> 0.01568
A11: ANOVA
A12: Source of Variation | B12: SS | C12: df | D12: MS | E12: F | F12: P-value | G12: F crit
A13: Between Groups | B13: =B16-DEVSQ(ASFData!$A:$A)-DEVSQ(ASFData!$B:$B)-DEVSQ(ASFData!$C:$C)-DEVSQ(ASFData!$D:$D) -> 11.621695 | C13: =J2-1 -> 3 | D13: =B13/C13 -> 3.8738983 | E13: =D13/D14 -> 88.218579 | F13: =_xlfn.F.DIST.RT(E13,C13,C14) -> 3.6292891e-10 | G13: =_xlfn.F.INV.RT(G17,C13,C14) -> 3.2388715
A14: Within Groups | B14: =B16-B13 -> 0.7026 | C14: =J3-J2 -> 16 | D14: =B14/C14 -> 0.0439125
A16: Total | B16: =DEVSQ(ASFData!$A$1:$D$6) -> 12.324295 | C16: =C13+C14 -> 19
E17: Level of significance | G17: 0.05

Sheet TK4
A1: Tukey Kramer Multiple Comparisons
B3: Sample | C3: Sample | F3: Absolute | G3: Std. Error | H3: Critical
A4: Group | B4: Mean | C4: Size | E4: Comparison | F4: Difference | G4: of Difference | H4: Range | I4: =IF(B15="","Results are NOT valid until Q Statistic is entered into B15","Results") -> Results
A5: ="1: " & 'One Way Anova'!A5 -> 1: In-aisle | B5: ='One Way Anova'!D5 -> 29.982 | C5: ='One Way Anova'!B5 -> 5 | E5: Group 1 to Group 2 | F5: =ABS($B$5-$B$6) -> 2.012 | G5: =SQRT(($B$14/2)*((1/$C$5)+(1/$C$6))) -> 0.093714993 | H5: =$B$15*$G$5 -> 0.37954572 | I5: =IF($F$5>$H$5,"Means are different","Means are not different") -> Means are different
A6: ="2: " & 'One Way Anova'!A6 -> 2: Front | B6: ='One Way Anova'!D6 -> 31.994 | C6: ='One Way Anova'!B6 -> 5 | E6: Group 1 to Group 3 | F6: =ABS($B$5-$B$7) -> 0.93 | G6: =SQRT(($B$14/2)*((1/$C$5)+(1/$C$7))) -> 0.093714993 | H6: =$B$15*$G$6 -> 0.37954572 | I6: =IF($F$6>$H$6,"Means are different","Means are not different") -> Means are different
A7: ="3: " & 'One Way Anova'!A7 -> 3: Kiosk | B7: ='One Way Anova'!D7 -> 30.912 | C7: ='One Way Anova'!B7 -> 5 | E7: Group 1 to Group 4 | F7: =ABS($B$5-$B$8) -> 0.352 | G7: =SQRT(($B$14/2)*((1/$C$5)+(1/$C$8))) -> 0.093714993 | H7: =$B$15*$G$7 -> 0.37954572 | I7: =IF($F$7>$H$7,"Means are different","Means are not different") -> Means are not different
A8: ="4: " & 'One Way Anova'!A8 -> 4: Expert | B8: ='One Way Anova'!D8 -> 30.334 | C8: ='One Way Anova'!B8 -> 5 | E8: Group 2 to Group 3 | F8: =ABS($B$6-$B$7) -> 1.082 | G8: =SQRT(($B$14/2)*((1/$C$6)+(1/$C$7))) -> 0.093714993 | H8: =$B$15*$G$8 -> 0.37954572 | I8: =IF($F$8>$H$8,"Means are different","Means are not different") -> Means are different
E9: Group 2 to Group 4 | F9: =ABS($B$6-$B$8) -> 1.66 | G9: =SQRT(($B$14/2)*((1/$C$6)+(1/$C$8))) -> 0.093714993 | H9: =$B$15*$G$9 -> 0.37954572 | I9: =IF($F$9>$H$9,"Means are different","Means are not different") -> Means are different
A10: Other Data | E10: Group 3 to Group 4 | F10: =ABS($B$7-$B$8) -> 0.578 | G10: =SQRT(($B$14/2)*((1/$C$7)+(1/$C$8))) -> 0.093714993 | H10: =$B$15*$G$10 -> 0.37954572 | I10: =IF($F$10>$H$10,"Means are different","Means are not different") -> Means are different
A11: Level of significance | B11: ='One Way Anova'!G17 -> 0.05
A12: Numerator d.f. | B12: ='One Way Anova'!J2 -> 4
A13: Denominator d.f. | B13: ='One Way Anova'!C14 -> 16
A14: MSW | B14: ='One Way Anova'!D14 -> 0.0439125
A15: Q Statistic | B15: 4.05

Sheet TK3
A1: Tukey Kramer Multiple Comparisons
B3: Sample | C3: Sample | F3: Absolute | G3: Std. Error | H3: Critical
A4: Group | B4: Mean | C4: Size | E4: Comparison | F4: Difference | G4: of Difference | H4: Range | I4: =IF(B14="","Results are NOT valid until Q Statistic is entered into B15","Results") -> Results
A5: ="1: " & [2]COMPUTE_FORMULAS!A5 -> 1: =ASFData!A1 | B5: =[2]COMPUTE_FORMULAS!D5 -> =AVERAGE(ASFData!$A:$A) | C5: =[2]COMPUTE_FORMULAS!B5 -> =COUNT(ASFData!$A:$A) | E5: Group 1 to Group 2 | F5: =ABS($B$5-$B$6) -> #VALUE! | G5: =SQRT(($B$13/2)*((1/$C$5)+(1/$C$6))) -> #VALUE! | H5: =$B$14*$G$5 -> #VALUE! | I5: =IF($F$5>$H$5,"Means are different","Means are not different") -> #VALUE!
A6: ="2: " & [2]COMPUTE_FORMULAS!A6 -> 2: =ASFData!B1 | B6: =[2]COMPUTE_FORMULAS!D6 -> =AVERAGE(ASFData!$B:$B) | C6: =[2]COMPUTE_FORMULAS!B6 -> =COUNT(ASFData!$B:$B) | E6: Group 1 to Group 3 | F6: =ABS($B$5-$B$7) -> #VALUE! | G6: =SQRT(($B$13/2)*((1/$C$5)+(1/$C$7))) -> #VALUE! | H6: =$B$14*$G$6 -> #VALUE! | I6: =IF($F$6>$H$6,"Means are different","Means are not different") -> #VALUE!
A7: ="3: " & [2]COMPUTE_FORMULAS!A7 -> 3: =ASFData!C1 | B7: =[2]COMPUTE_FORMULAS!D7 -> =AVERAGE(ASFData!$C:$C) | C7: =[2]COMPUTE_FORMULAS!B7 -> =COUNT(ASFData!$C:$C) | E7: Group 2 to Group 3 | F7: =ABS($B$6-$B$7) -> #VALUE! | G7: =SQRT(($B$13/2)*((1/$C$6)+(1/$C$7))) -> #VALUE! | H7: =$B$14*$G$7 -> #VALUE! | I7: =IF($F$7>$H$7,"Means are different","Means are not different") -> #VALUE!
A9: Other Data
A10: Level of significance | B10: =[2]COMPUTE_FORMULAS!G17 -> 0.05
A11: Numerator d.f. | B11: =[2]COMPUTE_FORMULAS!J2 -> =COUNTA(ASFData!$1:$1)
A12: Denominator d.f. | B12: =[2]COMPUTE_FORMULAS!C14 -> =J3-J2
A13: MSW | B13: =[2]COMPUTE!D14 -> 0.0439125
A14: Q Statistic | B14: 4.05

Sheet TK5
A1: Tukey Kramer Multiple Comparisons
B3: Sample | C3: Sample | F3: Absolute | G3: Std. Error | H3: Critical
A4: Group | B4: Mean | C4: Size | E4: Comparison | F4: Difference | G4: of Difference | H4: Range | I4: Results
A5: ="1: " & [2]COMPUTE_FORMULAS!A5 -> 1: =ASFData!A1 | B5: =[2]COMPUTE_FORMULAS!D5 -> =AVERAGE(ASFData!$A:$A) | C5: =[2]COMPUTE_FORMULAS!B5 -> =COUNT(ASFData!$A:$A) | E5: Group 1 to Group 2 | F5: =ABS($B$5-$B$6) -> #VALUE! | G5: =SQRT(($B$15/2)*((1/$C$5)+(1/$C$6))) -> #VALUE! | H5: =$B$16*$G$5 -> #VALUE! | I5: =IF($F$5>$H$5,"Means are different","Means are not different") -> #VALUE!
A6: ="2: " & [2]COMPUTE_FORMULAS!A6 -> 2: =ASFData!B1 | B6: =[2]COMPUTE_FORMULAS!D6 -> =AVERAGE(ASFData!$B:$B) | C6: =[2]COMPUTE_FORMULAS!B6 -> =COUNT(ASFData!$B:$B) | E6: Group 1 to Group 3 | F6: =ABS($B$5-$B$7) -> #VALUE! | G6: =SQRT(($B$15/2)*((1/$C$5)+(1/$C$7))) -> #VALUE! | H6: =$B$16*$G$6 -> #VALUE! | I6: =IF($F$6>$H$6,"Means are different","Means are not different") -> #VALUE!
A7: ="3: " & [2]COMPUTE_FORMULAS!A7 -> 3: =ASFData!C1 | B7: =[2]COMPUTE_FORMULAS!D7 -> =AVERAGE(ASFData!$C:$C) | C7: =[2]COMPUTE_FORMULAS!B7 -> =COUNT(ASFData!$C:$C) | E7: Group 1 to Group 4 | F7: =ABS($B$5-$B$8) -> #VALUE! | G7: =SQRT(($B$15/2)*((1/$C$5)+(1/$C$8))) -> #VALUE! | H7: =$B$16*$G$7 -> #VALUE! | I7: =IF($F$7>$H$7,"Means are different","Means are not different") -> #VALUE!
